Workbook

Sheet Flights
A1: Date | B1: WeekNum | C1: WeekDay | D1: Flight | E1: Airline | F1: Origin | G1: Destination | H1: Destination City | I1: Destination State | J1: Scheduled Departure | K1: Scheduled Departure Hour | L1: Departure | M1: Departure Delay | N1: Length (min) | O1: Length(hr) | P1: Distance | Q1: AverageSpreed | R1: Scheduled Arrival | S1: Arrival | T1: Arrival Delay | U1: Status | V1: Depart Type | W1: Compansation | X1: Cancellation Reason
A2: 42005 | B2: =WEEKNUM(Flights!$A2,2) -> 1 | C2: =WEEKDAY(Flights!$A2,2) -> 4 | D2: AA258 | E2: American Airlines | F2: LAX | G2: MIA | H2: =_xlfn.XLOOKUP(Flights!$G2,Airports!$A$2:$A$77,Airports!$D$2:$D$77,"Not Code Found") -> Miami | I2: =_xlfn.XLOOKUP(Flights!$G2,Airports!$A$2:$A$77,Airports!$E$2:$E$77,"Not Code Found") -> FL | J2: 0.013888889 | K2: =HOUR(Flights!$J2) -> 0 | L2: 0.010416667 | M2: -5 | N2: 281 | O2: =Flights!$N2/60 -> 4.6833333 | P2: 2342 | Q2: =Flights!$P2/Flights!$O2 -> 500.07117 | R2: 0.33680556 | S2: 0.33055556 | T2: -9 | U2: =IF(Flights!$T2="","Cancel",IF(Flights!$T2>15,"Delay","On Time")) -> On Time | V2: =IF(Flights!$U2<>"Delay","",IF(Flights!$T2>120,"Severe",IF(Flights!$T2>60,"Major","Moderate"))) | W2: =IF(OR(AND(Flights!$U2="Cancel",Flights!$X2="Airline/Carrier"),Flights!$V2="severe"),"Yes","No") -> No
A3: 42005 | B3: =WEEKNUM(Flights!$A3,2) -> 1 | C3: =WEEKDAY(Flights!$A3,2) -> 4 | D3: WN2077 | E3: Southwest | F3: LAX | G3: ABQ | H3: =_xlfn.XLOOKUP(Flights!$G3,Airports!$A$2:$A$77,Airports!$D$2:$D$77,"Not Code Found") -> Albuquerque | I3: =_xlfn.XLOOKUP(Flights!$G3,Airports!$A$2:$A$77,Airports!$E$2:$E$77,"Not Code Found") -> NM | J3: 0.40972222 | K3: =HOUR(Flights!$J3) -> 9 | L3: 0.40486111 | M3: -7 | N3: 109 | O3: =Flights!$N3/60 -> 1.8166667 | P3: 677 | Q3: =Flights!$P3/Flights!$O3 -> 372.66055 | R3: 0.52430556 | S3: 0.52222222 | T3: -3 | U3: =IF(Flights!$T3="","Cancel",IF(Flights!$T3>15,"Delay","On Time")) -> On Time | V3: =IF(Flights!$U3<>"Delay","",IF(Flights!$T3>120,"Severe",IF(Flights!$T3>60,"Major","Moderate"))) | W3: =IF(OR(AND(Flights!$U3="Cancel",Flights!$X3="Airline/Carrier"),Flights!$V3="severe"),"Yes","No") -> No
A4: 42005 | B4: =WEEKNUM(Flights!$A4,2) -> 1 | C4: =WEEKDAY(Flights!$A4,2) -> 4 | D4: US726 | E4: US Airways | F4: LAX | G4: PIT | H4: =_xlfn.XLOOKUP(Flights!$G4,Airports!$A$2:$A$77,Airports!$D$2:$D$77,"Not Code Found") -> Pittsburgh | I4: =_xlfn.XLOOKUP(Flights!$G4,Airports!$A$2:$A$77,Airports!$E$2:$E$77,"Not Code Found") -> PA | J4: 0.47916667 | K4: =HOUR(Flights!$J4) -> 11 | L4: 0.48680556 | M4: 11 | N4: 282 | O4: =Flights!$N4/60 -> 4.7 | P4: 2136 | Q4: =Flights!$P4/Flights!$O4 -> 454.46809 | R4: 0.79097222 | S4: 0.80763889 | T4: 24 | U4: =IF(Flights!$T4="","Cancel",IF(Flights!$T4>15,"Delay","On Time")) -> Delay | V4: =IF(Flights!$U4<>"Delay","",IF(Flights!$T4>120,"Severe",IF(Flights!$T4>60,"Major","Moderate"))) -> Moderate | W4: =IF(OR(AND(Flights!$U4="Cancel",Flights!$X4="Airline/Carrier"),Flights!$V4="severe"),"Yes","No") -> No
A5: 42005 | B5: =WEEKNUM(Flights!$A5,2) -> 1 | C5: =WEEKDAY(Flights!$A5,2) -> 4 | D5: AA2419 | E5: American Airlines | F5: LAX | G5: DFW | H5: =_xlfn.XLOOKUP(Flights!$G5,Airports!$A$2:$A$77,Airports!$D$2:$D$77,"Not Code Found") -> Dallas | I5: =_xlfn.XLOOKUP(Flights!$G5,Airports!$A$2:$A$77,Airports!$E$2:$E$77,"Not Code Found") -> TX | J5: 0.48958333 | K5: =HOUR(Flights!$J5) -> 11 | L5: 0.50972222 | M5: 29 | N5: 194 | O5: =Flights!$N5/60 -> 3.2333333 | P5: 1235 | Q5: =Flights!$P5/Flights!$O5 -> 381.95876 | R5: 0.70138889 | S5: 0.72777778 | T5: 38 | U5: =IF(Flights!$T5="","Cancel",IF(Flights!$T5>15,"Delay","On Time")) -> Delay | V5: =IF(Flights!$U5<>"Delay","",IF(Flights!$T5>120,"Severe",IF(Flights!$T5>60,"Major","Moderate"))) -> Moderate | W5: =IF(OR(AND(Flights!$U5="Cancel",Flights!$X5="Airline/Carrier"),Flights!$V5="severe"),"Yes","No") -> No
A6: 42005 | B6: =WEEKNUM(Flights!$A6,2) -> 1 | C6: =WEEKDAY(Flights!$A6,2) -> 4 | D6: OO4535 | E6: Skywest | F6: LAX | G6: LAS | H6: =_xlfn.XLOOKUP(Flights!$G6,Airports!$A$2:$A$77,Airports!$D$2:$D$77,"Not Code Found") -> Las Vegas | I6: =_xlfn.XLOOKUP(Flights!$G6,Airports!$A$2:$A$77,Airports!$E$2:$E$77,"Not Code Found") -> NV | J6: 0.52777778 | K6: =HOUR(Flights!$J6) -> 12 | L6: 0.52569444 | M6: -3 | N6: 71 | O6: =Flights!$N6/60 -> 1.1833333 | P6: 236 | Q6: =Flights!$P6/Flights!$O6 -> 199.43662 | R6: 0.57916667 | S6: 0.575 | T6: -6 | U6: =IF(Flights!$T6="","Cancel",IF(Flights!$T6>15,"Delay","On Time")) -> On Time | V6: =IF(Flights!$U6<>"Delay","",IF(Flights!$T6>120,"Severe",IF(Flights!$T6>60,"Major","Moderate"))) | W6: =IF(OR(AND(Flights!$U6="Cancel",Flights!$X6="Airline/Carrier"),Flights!$V6="severe"),"Yes","No") -> No
A7: 42005 | B7: =WEEKNUM(Flights!$A7,2) -> 1 | C7: =WEEKDAY(Flights!$A7,2) -> 4 | D7: VX412 | E7: Virgin America | F7: LAX | G7: JFK | H7: =_xlfn.XLOOKUP(Flights!$G7,Airports!$A$2:$A$77,Airports!$D$2:$D$77,"Not Code Found") -> New York | I7: =_xlfn.XLOOKUP(Flights!$G7,Airports!$A$2:$A$77,Airports!$E$2:$E$77,"Not Code Found") -> NY | J7: 0.56944444 | K7: =HOUR(Flights!$J7) -> 13 | L7: 0.56597222 | M7: -5 | N7: 298 | O7: =Flights!$N7/60 -> 4.9666667 | P7: 2475 | Q7: =Flights!$P7/Flights!$O7 -> 498.32215 | R7: 0.91666667 | S7: 0.89791667 | T7: -27 | U7: =IF(Flights!$T7="","Cancel",IF(Flights!$T7>15,"Delay","On Time")) -> On Time | V7: =IF(Flights!$U7<>"Delay","",IF(Flights!$T7>120,"Severe",IF(Flights!$T7>60,"Major","Moderate"))) | W7: =IF(OR(AND(Flights!$U7="Cancel",Flights!$X7="Airline/Carrier"),Flights!$V7="severe"),"Yes","No") -> No
A8: 42005 | B8: =WEEKNUM(Flights!$A8,2) -> 1 | C8: =WEEKDAY(Flights!$A8,2) -> 4 | D8: AA28 | E8: American Airlines | F8: LAX | G8: MIA | H8: =_xlfn.XLOOKUP(Flights!$G8,Airports!$A$2:$A$77,Airports!$D$2:$D$77,"Not Code Found") -> Miami | I8: =_xlfn.XLOOKUP(Flights!$G8,Airports!$A$2:$A$77,Airports!$E$2:$E$77,"Not Code Found") -> FL | J8: 0.625 | K8: =HOUR(Flights!$J8) -> 15 | L8: 0.62222222 | M8: -4 | N8: 305 | O8: =Flights!$N8/60 -> 5.0833333 | P8: 2342 | Q8: =Flights!$P8/Flights!$O8 -> 460.72131 | R8: 0.95138889 | S8: 0.95902778 | T8: 11 | U8: =IF(Flights!$T8="","Cancel",IF(Flights!$T8>15,"Delay","On Time")) -> On Time | V8: =IF(Flights!$U8<>"Delay","",IF(Flights!$T8>120,"Severe",IF(Flights!$T8>60,"Major","Moderate"))) | W8: =IF(OR(AND(Flights!$U8="Cancel",Flights!$X8="Airline/Carrier"),Flights!$V8="severe"),"Yes","No") -> No
A9: 42005 | B9: =WEEKNUM(Flights!$A9,2) -> 1 | C9: =WEEKDAY(Flights!$A9,2) -> 4 | D9: OO6528 | E9: Skywest | F9: LAX | G9: PHX | H9: =_xlfn.XLOOKUP(Flights!$G9,Airports!$A$2:$A$77,Airports!$D$2:$D$77,"Not Code Found") -> Phoenix | I9: =_xlfn.XLOOKUP(Flights!$G9,Airports!$A$2:$A$77,Airports!$E$2:$E$77,"Not Code Found") -> AZ | J9: 0.69513889 | K9: =HOUR(Flights!$J9) -> 16 | L9: 0.69027778 | M9: -7 | N9: 80 | O9: =Flights!$N9/60 -> 1.3333333 | P9: 370 | Q9: =Flights!$P9/Flights!$O9 -> 277.5 | R9: 0.79513889 | S9: 0.7875 | T9: -11 | U9: =IF(Flights!$T9="","Cancel",IF(Flights!$T9>15,"Delay","On Time")) -> On Time | V9: =IF(Flights!$U9<>"Delay","",IF(Flights!$T9>120,"Severe",IF(Flights!$T9>60,"Major","Moderate"))) | W9: =IF(OR(AND(Flights!$U9="Cancel",Flights!$X9="Airline/Carrier"),Flights!$V9="severe"),"Yes","No") -> No
A10: 42005 | B10: =WEEKNUM(Flights!$A10,2) -> 1 | C10: =WEEKDAY(Flights!$A10,2) -> 4 | D10: AS461 | E10: Alaska Airlines | F10: LAX | G10: SEA | H10: =_xlfn.XLOOKUP(Flights!$G10,Airports!$A$2:$A$77,Airports!$D$2:$D$77,"Not Code Found") -> Seattle | I10: =_xlfn.XLOOKUP(Flights!$G10,Airports!$A$2:$A$77,Airports!$E$2:$E$77,"Not Code Found") -> WA | J10: 0.73611111 | K10: =HOUR(Flights!$J10) -> 17 | L10: 0.73125 | M10: -7 | N10: 162 | O10: =Flights!$N10/60 -> 2.7 | P10: 954 | Q10: =Flights!$P10/Flights!$O10 -> 353.33333 | R10: 0.84791667 | S10: 0.84375 | T10: -6 | U10: =IF(Flights!$T10="","Cancel",IF(Flights!$T10>15,"Delay","On Time")) -> On Time | V10: =IF(Flights!$U10<>"Delay","",IF(Flights!$T10>120,"Severe",IF(Flights!$T10>60,"Major","Moderate"))) | W10: =IF(OR(AND(Flights!$U10="Cancel",Flights!$X10="Airline/Carrier"),Flights!$V10="severe"),"Yes","No") -> No
A11: 42005 | B11: =WEEKNUM(Flights!$A11,2) -> 1 | C11: =WEEKDAY(Flights!$A11,2) -> 4 | D11: AA219 | E11: American Airlines | F11: LAX | G11: SFO | H11: =_xlfn.XLOOKUP(Flights!$G11,Airports!$A$2:$A$77,Airports!$D$2:$D$77,"Not Code Found") -> San Francisco | I11: =_xlfn.XLOOKUP(Flights!$G11,Airports!$A$2:$A$77,Airports!$E$2:$E$77,"Not Code Found") -> CA | J11: 0.75 | K11: =HOUR(Flights!$J11) -> 18 | L11: 0.74791667 | M11: -3 | N11: 76 | O11: =Flights!$N11/60 -> 1.2666667 | P11: 337 | Q11: =Flights!$P11/Flights!$O11 -> 266.05263 | R11: 0.80555556 | S11: 0.80069444 | T11: -7 | U11: =IF(Flights!$T11="","Cancel",IF(Flights!$T11>15,"Delay","On Time")) -> On Time | V11: =IF(Flights!$U11<>"Delay","",IF(Flights!$T11>120,"Severe",IF(Flights!$T11>60,"Major","Moderate"))) | W11: =IF(OR(AND(Flights!$U11="Cancel",Flights!$X11="Airline/Carrier"),Flights!$V11="severe"),"Yes","No") -> No
A12: 42005 | B12: =WEEKNUM(Flights!$A12,2) -> 1 | C12: =WEEKDAY(Flights!$A12,2) -> 4 | D12: NK310 | E12: Spirit | F12: LAX | G12: FLL | H12: =_xlfn.XLOOKUP(Flights!$G12,Airports!$A$2:$A$77,Airports!$D$2:$D$77,"Not Code Found") -> Fort Lauderdale | I12: =_xlfn.XLOOKUP(Flights!$G12,Airports!$A$2:$A$77,Airports!$E$2:$E$77,"Not Code Found") -> FL | J12: 0.875 | K12: =HOUR(Flights!$J12) -> 21 | L12: 0.88055556 | M12: 8 | N12: 286 | O12: =Flights!$N12/60 -> 4.7666667 | P12: 2342 | Q12: =Flights!$P12/Flights!$O12 -> 491.32867 | R12: 0.19513889 | S12: 0.20416667 | T12: 13 | U12: =IF(Flights!$T12="","Cancel",IF(Flights!$T12>15,"Delay","On Time")) -> On Time | V12: =IF(Flights!$U12<>"Delay","",IF(Flights!$T12>120,"Severe",IF(Flights!$T12>60,"Major","Moderate"))) | W12: =IF(OR(AND(Flights!$U12="Cancel",Flights!$X12="Airline/Carrier"),Flights!$V12="severe"),"Yes","No") -> No
A13: 42005 | B13: =WEEKNUM(Flights!$A13,2) -> 1 | C13: =WEEKDAY(Flights!$A13,2) -> 4 | D13: OO2578 | E13: Skywest | F13: LAX | G13: SJC | H13: =_xlfn.XLOOKUP(Flights!$G13,Airports!$A$2:$A$77,Airports!$D$2:$D$77,"Not Code Found") -> San Jose | I13: =_xlfn.XLOOKUP(Flights!$G13,Airports!$A$2:$A$77,Airports!$E$2:$E$77,"Not Code Found") -> CA | J13: 0.89236111 | K13: =HOUR(Flights!$J13) -> 21 | L13: 0.91736111 | M13: 36 | N13: 65 | O13: =Flights!$N13/60 -> 1.0833333 | P13: 308 | Q13: =Flights!$P13/Flights!$O13 -> 284.30769 | R13: 0.94097222 | S13: 0.9625 | T13: 31 | U13: =IF(Flights!$T13="","Cancel",IF(Flights!$T13>15,"Delay","On Time")) -> Delay | V13: =IF(Flights!$U13<>"Delay","",IF(Flights!$T13>120,"Severe",IF(Flights!$T13>60,"Major","Moderate"))) -> Moderate | W13: =IF(OR(AND(Flights!$U13="Cancel",Flights!$X13="Airline/Carrier"),Flights!$V13="severe"),"Yes","No") -> No
... A74: 42010 | B74: =WEEKNUM(Flights!$A74,2) -> 2 | C74: =WEEKDAY(Flights!$A74,2) -> 2 | D74: AA247 | E74: American Airlines | F74: LAX | G74: KOA | H74: =_xlfn.XLOOKUP(Flights!$G74,Airports!$A$2:$A$77,Airports!$D$2:$D$77,"Not Code Found") -> Kona | I74: =_xlfn.XLOOKUP(Flights!$G74,Airports!$A$2:$A$77,Airports!$E$2:$E$77,"Not Code Found") -> HI | J74: 0.71527778 | K74: =HOUR(Flights!$J74) -> 17 | L74: 0.70902778 | M74: -9 | N74: 358 | O74: =Flights!$N74/60 -> 5.9666667 | P74: 2504 | Q74: =Flights!$P74/Flights!$O74 -> 419.6648 | R74: 0.87916667 | S74: 0.87430556 | T74: -7 | U74: =IF(Flights!$T74="","Cancel",IF(Flights!$T74>15,"Delay","On Time")) -> On Time | V74: =IF(Flights!$U74<>"Delay","",IF(Flights!$T74>120,"Severe",IF(Flights!$T74>60,"Major","Moderate"))) | W74: =IF(OR(AND(Flights!$U74="Cancel",Flights!$X74="Airline/Carrier"),Flights!$V74="severe"),"Yes","No") -> No
A75: 42010 | B75: =WEEKNUM(Flights!$A75,2) -> 2 | C75: =WEEKDAY(Flights!$A75,2) -> 2 | D75: OO4678 | E75: Skywest | F75: LAX | G75: BOI | H75: =_xlfn.XLOOKUP(Flights!$G75,Airports!$A$2:$A$77,Airports!$D$2:$D$77,"Not Code Found") -> Boise | I75: =_xlfn.XLOOKUP(Flights!$G75,Airports!$A$2:$A$77,Airports!$E$2:$E$77,"Not Code Found") -> ID | J75: 0.77083333 | K75: =HOUR(Flights!$J75) -> 18 | L75: 0 | O75: =Flights!$N75/60 -> 0 | P75: 674 | Q75: =Flights!$P75/Flights!$O75 -> #DIV/0! | R75: 0.89791667 | S75: 0 | U75: =IF(Flights!$T75="","Cancel",IF(Flights!$T75>15,"Delay","On Time")) -> Cancel | V75: =IF(Flights!$U75<>"Delay","",IF(Flights!$T75>120,"Severe",IF(Flights!$T75>60,"Major","Moderate"))) | W75: =IF(OR(AND(Flights!$U75="Cancel",Flights!$X75="Airline/Carrier"),Flights!$V75="severe"),"Yes","No") -> No | X75: Weather
A76: 42010 | B76: =WEEKNUM(Flights!$A76,2) -> 2 | C76: =WEEKDAY(Flights!$A76,2) -> 2 | D76: AA1410 | E76: American Airlines | F76: LAX | G76: LAS | H76: =_xlfn.XLOOKUP(Flights!$G76,Airports!$A$2:$A$77,Airports!$D$2:$D$77,"Not Code Found") -> Las Vegas | I76: =_xlfn.XLOOKUP(Flights!$G76,Airports!$A$2:$A$77,Airports!$E$2:$E$77,"Not Code Found") -> NV | J76: 0.93333333 | K76: =HOUR(Flights!$J76) -> 22 | L76: 0.92916667 | M76: -6 | N76: 64 | O76: =Flights!$N76/60 -> 1.0666667 | P76: 236 | Q76: =Flights!$P76/Flights!$O76 -> 221.25 | R76: 0.98263889 | S76: 0.97361111 | T76: -13 | U76: =IF(Flights!$T76="","Cancel",IF(Flights!$T76>15,"Delay","On Time")) -> On Time | V76: =IF(Flights!$U76<>"Delay","",IF(Flights!$T76>120,"Severe",IF(Flights!$T76>60,"Major","Moderate"))) | W76: =IF(OR(AND(Flights!$U76="Cancel",Flights!$X76="Airline/Carrier"),Flights!$V76="severe"),"Yes","No") -> No
A77: 42010 | B77: =WEEKNUM(Flights!$A77,2) -> 2 | C77: =WEEKDAY(Flights!$A77,2) -> 2 | D77: B6688 | E77: JetBlue | F77: LAX | G77: BOS | H77: =_xlfn.XLOOKUP(Flights!$G77,Airports!$A$2:$A$77,Airports!$D$2:$D$77,"Not Code Found") -> Boston | I77: =_xlfn.XLOOKUP(Flights!$G77,Airports!$A$2:$A$77,Airports!$E$2:$E$77,"Not Code Found") -> MA | J77: 0.99236111 | K77: =HOUR(Flights!$J77) -> 23 | L77: 0.03125 | M77: 56 | N77: 303 | O77: =Flights!$N77/60 -> 5.05 | P77: 2611 | Q77: =Flights!$P77/Flights!$O77 -> 517.0297 | R77: 0.33958333 | S77: 0.36666667 | T77: 39 | U77: =IF(Flights!$T77="","Cancel",IF(Flights!$T77>15,"Delay","On Time")) -> Delay | V77: =IF(Flights!$U77<>"Delay","",IF(Flights!$T77>120,"Severe",IF(Flights!$T77>60,"Major","Moderate"))) -> Moderate | W77: =IF(OR(AND(Flights!$U77="Cancel",Flights!$X77="Airline/Carrier"),Flights!$V77="severe"),"Yes","No") -> No
A78: 42011 | B78: =WEEKNUM(Flights!$A78,2) -> 2 | C78: =WEEKDAY(Flights!$A78,2) -> 3 | D78: AA387 | E78: American Airlines | F78: LAX | G78: AUS | H78: =_xlfn.XLOOKUP(Flights!$G78,Airports!$A$2:$A$77,Airports!$D$2:$D$77,"Not Code Found") -> Austin | I78: =_xlfn.XLOOKUP(Flights!$G78,Airports!$A$2:$A$77,Airports!$E$2:$E$77,"Not Code Found") -> TX | J78: 0.26736111 | K78: =HOUR(Flights!$J78) -> 6 | L78: 0.2625 | M78: -7 | N78: 186 | O78: =Flights!$N78/60 -> 3.1 | P78: 1242 | Q78: =Flights!$P78/Flights!$O78 -> 400.64516 | R78: 0.47291667 | S78: 0.475 | T78: 3 | U78: =IF(Flights!$T78="","Cancel",IF(Flights!$T78>15,"Delay","On Time")) -> On Time | V78: =IF(Flights!$U78<>"Delay","",IF(Flights!$T78>120,"Severe",IF(Flights!$T78>60,"Major","Moderate"))) | W78: =IF(OR(AND(Flights!$U78="Cancel",Flights!$X78="Airline/Carrier"),Flights!$V78="severe"),"Yes","No") -> No
A79: 42011 | B79: =WEEKNUM(Flights!$A79,2) -> 2 | C79: =WEEKDAY(Flights!$A79,2) -> 3 | D79: WN2864 | E79: Southwest | F79: LAX | G79: BWI | H79: =_xlfn.XLOOKUP(Flights!$G79,Airports!$A$2:$A$77,Airports!$D$2:$D$77,"Not Code Found") -> Baltimore | I79: =_xlfn.XLOOKUP(Flights!$G79,Airports!$A$2:$A$77,Airports!$E$2:$E$77,"Not Code Found") -> MD | J79: 0.29166667 | K79: =HOUR(Flights!$J79) -> 7 | L79: 0.29722222 | M79: 8 | N79: 283 | O79: =Flights!$N79/60 -> 4.7166667 | P79: 2329 | Q79: =Flights!$P79/Flights!$O79 -> 493.78092 | R79: 0.62152778 | S79: 0.61875 | T79: -4 | U79: =IF(Flights!$T79="","Cancel",IF(Flights!$T79>15,"Delay","On Time")) -> On Time | V79: =IF(Flights!$U79<>"Delay","",IF(Flights!$T79>120,"Severe",IF(Flights!$T79>60,"Major","Moderate"))) | W79: =IF(OR(AND(Flights!$U79="Cancel",Flights!$X79="Airline/Carrier"),Flights!$V79="severe"),"Yes","No") -> No
A80: 42011 | B80: =WEEKNUM(Flights!$A80,2) -> 2 | C80: =WEEKDAY(Flights!$A80,2) -> 3 | D80: UA1203 | E80: United | F80: LAX | G80: SFO | H80: =_xlfn.XLOOKUP(Flights!$G80,Airports!$A$2:$A$77,Airports!$D$2:$D$77,"Not Code Found") -> San Francisco | I80: =_xlfn.XLOOKUP(Flights!$G80,Airports!$A$2:$A$77,Airports!$E$2:$E$77,"Not Code Found") -> CA | J80: 0.33333333 | K80: =HOUR(Flights!$J80) -> 8 | L80: 0.33680556 | M80: 5 | N80: 75 | O80: =Flights!$N80/60 -> 1.25 | P80: 337 | Q80: =Flights!$P80/Flights!$O80 -> 269.6 | R80: 0.39930556 | S80: 0.38888889 | T80: -15 | U80: =IF(Flights!$T80="","Cancel",IF(Flights!$T80>15,"Delay","On Time")) -> On Time | V80: =IF(Flights!$U80<>"Delay","",IF(Flights!$T80>120,"Severe",IF(Flights!$T80>60,"Major","Moderate"))) | W80: =IF(OR(AND(Flights!$U80="Cancel",Flights!$X80="Airline/Carrier"),Flights!$V80="severe"),"Yes","No") -> No
A81: 42011 | B81: =WEEKNUM(Flights!$A81,2) -> 2 | C81: =WEEKDAY(Flights!$A81,2) -> 3 | D81: UA1658 | E81: United | F81: LAX | G81: DEN | H81: =_xlfn.XLOOKUP(Flights!$G81,Airports!$A$2:$A$77,Airports!$D$2:$D$77,"Not Code Found") -> Denver | I81: =_xlfn.XLOOKUP(Flights!$G81,Airports!$A$2:$A$77,Airports!$E$2:$E$77,"Not Code Found") -> CO | J81: 0.34375 | K81: =HOUR(Flights!$J81) -> 8 | L81: 0.35 | M81: 9 | N81: 214 | O81: =Flights!$N81/60 -> 3.5666667 | P81: 862 | Q81: =Flights!$P81/Flights!$O81 -> 241.68224 | R81: 0.48611111 | S81: 0.54027778 | T81: 78 | U81: =IF(Flights!$T81="","Cancel",IF(Flights!$T81>15,"Delay","On Time")) -> Delay | V81: =IF(Flights!$U81<>"Delay","",IF(Flights!$T81>120,"Severe",IF(Flights!$T81>60,"Major","Moderate"))) -> Major | W81: =IF(OR(AND(Flights!$U81="Cancel",Flights!$X81="Airline/Carrier"),Flights!$V81="severe"),"Yes","No") -> No
A82: 42011 | B82: =WEEKNUM(Flights!$A82,2) -> 2 | C82: =WEEKDAY(Flights!$A82,2) -> 3 | D82: AA265 | E82: American Airlines | F82: LAX | G82: LIH | H82: =_xlfn.XLOOKUP(Flights!$G82,Airports!$A$2:$A$77,Airports!$D$2:$D$77,"Not Code Found") -> Lihue | I82: =_xlfn.XLOOKUP(Flights!$G82,Airports!$A$2:$A$77,Airports!$E$2:$E$77,"Not Code Found") -> HI | J82: 0.38541667 | K82: =HOUR(Flights!$J82) -> 9 | L82: 0.38055556 | M82: -7 | N82: 389 | O82: =Flights!$N82/60 -> 6.4833333 | P82: 2615 | Q82: =Flights!$P82/Flights!$O82 -> 403.3419 | R82: 0.56597222 | S82: 0.56736111 | T82: 2 | U82: =IF(Flights!$T82="","Cancel",IF(Flights!$T82>15,"Delay","On Time")) -> On Time | V82: =IF(Flights!$U82<>"Delay","",IF(Flights!$T82>120,"Severe",IF(Flights!$T82>60,"Major","Moderate"))) | W82: =IF(OR(AND(Flights!$U82="Cancel",Flights!$X82="Airline/Carrier"),Flights!$V82="severe"),"Yes","No") -> No
A83: 42011 | B83: =WEEKNUM(Flights!$A83,2) -> 2 | C83: =WEEKDAY(Flights!$A83,2) -> 3 | D83: WN2152 | E83: Southwest | F83: LAX | G83: SFO | H83: =_xlfn.XLOOKUP(Flights!$G83,Airports!$A$2:$A$77,Airports!$D$2:$D$77,"Not Code Found") -> San Francisco | I83: =_xlfn.XLOOKUP(Flights!$G83,Airports!$A$2:$A$77,Airports!$E$2:$E$77,"Not Code Found") -> CA | J83: 0.40972222 | K83: =HOUR(Flights!$J83) -> 9 | L83: 0.40902778 | M83: -1 | N83: 66 | O83: =Flights!$N83/60 -> 1.1 | P83: 337 | Q83: =Flights!$P83/Flights!$O83 -> 306.36364 | R83: 0.47222222 | S83: 0.45486111 | T83: -25 | U83: =IF(Flights!$T83="","Cancel",IF(Flights!$T83>15,"Delay","On Time")) -> On Time | V83: =IF(Flights!$U83<>"Delay","",IF(Flights!$T83>120,"Severe",IF(Flights!$T83>60,"Major","Moderate"))) | W83: =IF(OR(AND(Flights!$U83="Cancel",Flights!$X83="Airline/Carrier"),Flights!$V83="severe"),"Yes","No") -> No
A84: 42011 | B84: =WEEKNUM(Flights!$A84,2) -> 2 | C84: =WEEKDAY(Flights!$A84,2) -> 3 | D84: WN4304 | E84: Southwest | F84: LAX | G84: SJC | H84: =_xlfn.XLOOKUP(Flights!$G84,Airports!$A$2:$A$77,Airports!$D$2:$D$77,"Not Code Found") -> San Jose | I84: =_xlfn.XLOOKUP(Flights!$G84,Airports!$A$2:$A$77,Airports!$E$2:$E$77,"Not Code Found") -> CA | J84: 0.45833333 | K84: =HOUR(Flights!$J84) -> 11 | L84: 0.46111111 | M84: 4 | N84: 63 | O84: =Flights!$N84/60 -> 1.05 | P84: 308 | Q84: =Flights!$P84/Flights!$O84 -> 293.33333 | R84: 0.50347222 | S84: 0.50486111 | T84: 2 | U84: =IF(Flights!$T84="","Cancel",IF(Flights!$T84>15,"Delay","On Time")) -> On Time | V84: =IF(Flights!$U84<>"Delay","",IF(Flights!$T84>120,"Severe",IF(Flights!$T84>60,"Major","Moderate"))) | W84: =IF(OR(AND(Flights!$U84="Cancel",Flights!$X84="Airline/Carrier"),Flights!$V84="severe"),"Yes","No") -> No
A85: 42011 | B85: =WEEKNUM(Flights!$A85,2) -> 2 | C85: =WEEKDAY(Flights!$A85,2) -> 3 | D85: OO4825 | E85: Skywest | F85: LAX | G85: SJC | H85: =_xlfn.XLOOKUP(Flights!$G85,Airports!$A$2:$A$77,Airports!$D$2:$D$77,"Not Code Found") -> San Jose | I85: =_xlfn.XLOOKUP(Flights!$G85,Airports!$A$2:$A$77,Airports!$E$2:$E$77,"Not Code Found") -> CA | J85: 0.52777778 | K85: =HOUR(Flights!$J85) -> 12 | L85: 0.53472222 | M85: 10 | N85: 67 | O85: =Flights!$N85/60 -> 1.1166667 | P85: 308 | Q85: =Flights!$P85/Flights!$O85 -> 275.8209 | R85: 0.57986111 | S85: 0.58125 | T85: 2 | U85: =IF(Flights!$T85="","Cancel",IF(Flights!$T85>15,"Delay","On Time")) -> On Time | V85: =IF(Flights!$U85<>"Delay","",IF(Flights!$T85>120,"Severe",IF(Flights!$T85>60,"Major","Moderate"))) | W85: =IF(OR(AND(Flights!$U85="Cancel",Flights!$X85="Airline/Carrier"),Flights!$V85="severe"),"Yes","No") -> No
A86: 42011 | B86: =WEEKNUM(Flights!$A86,2) -> 2 | C86: =WEEKDAY(Flights!$A86,2) -> 3 | D86: OO6496 | E86: Skywest | F86: LAX | G86: COS | H86: =_xlfn.XLOOKUP(Flights!$G86,Airports!$A$2:$A$77,Airports!$D$2:$D$77,"Not Code Found") -> Colorado Springs | I86: =_xlfn.XLOOKUP(Flights!$G86,Airports!$A$2:$A$77,Airports!$E$2:$E$77,"Not Code Found") -> CO | J86: 0.79861111 | K86: =HOUR(Flights!$J86) -> 19 | L86: 0.79375 | M86: -7 | N86: 148 | O86: =Flights!$N86/60 -> 2.4666667 | P86: 833 | Q86: =Flights!$P86/Flights!$O86 -> 337.7027 | R86: 0.93194444 | S86: 0.93819444 | T86: 9 | U86: =IF(Flights!$T86="","Cancel",IF(Flights!$T86>15,"Delay","On Time")) -> On Time | V86: =IF(Flights!$U86<>"Delay","",IF(Flights!$T86>120,"Severe",IF(Flights!$T86>60,"Major","Moderate"))) | W86: =IF(OR(AND(Flights!$U86="Cancel",Flights!$X86="Airline/Carrier"),Flights!$V86="severe"),"Yes","No") -> No
A87: 42012 | B87: =WEEKNUM(Flights!$A87,2) -> 2 | C87: =WEEKDAY(Flights!$A87,2) -> 4 | D87: WN4236 | E87: Southwest | F87: LAX | G87: OAK | H87: =_xlfn.XLOOKUP(Flights!$G87,Airports!$A$2:$A$77,Airports!$D$2:$D$77,"Not Code Found") -> Oakland | I87: =_xlfn.XLOOKUP(Flights!$G87,Airports!$A$2:$A$77,Airports!$E$2:$E$77,"Not Code Found") -> CA | J87: 0.375 | K87: =HOUR(Flights!$J87) -> 9 | L87: 0.37361111 | M87: -2 | N87: 65 | O87: =Flights!$N87/60 -> 1.0833333 | P87: 337 | Q87: =Flights!$P87/Flights!$O87 -> 311.07692 | R87: 0.43055556 | S87: 0.41875 | T87: -17 | U87: =IF(Flights!$T87="","Cancel",IF(Flights!$T87>15,"Delay","On Time")) -> On Time | V87: =IF(Flights!$U87<>"Delay","",IF(Flights!$T87>120,"Severe",IF(Flights!$T87>60,"Major","Moderate"))) | W87: =IF(OR(AND(Flights!$U87="Cancel",Flights!$X87="Airline/Carrier"),Flights!$V87="severe"),"Yes","No") -> No
... A95: 42012 | B95: =WEEKNUM(Flights!$A95,2) -> 2 | C95: =WEEKDAY(Flights!$A95,2) -> 4 | D95: UA438 | E95: United | F95: LAX | G95: ORD | H95: =_xlfn.XLOOKUP(Flights!$G95,Airports!$A$2:$A$77,Airports!$D$2:$D$77,"Not Code Found") -> Chicago | I95: =_xlfn.XLOOKUP(Flights!$G95,Airports!$A$2:$A$77,Airports!$E$2:$E$77,"Not Code Found") -> IL | J95: 0.71458333 | K95: =HOUR(Flights!$J95) -> 17 | L95: 0.71111111 | M95: -5 | N95: 349 | O95: =Flights!$N95/60 -> 5.8166667 | P95: 1744 | Q95: =Flights!$P95/Flights!$O95 -> 299.82808 | R95: 0.97222222 | S95: 0.036805556 | T95: 93 | U95: =IF(Flights!$T95="","Cancel",IF(Flights!$T95>15,"Delay","On Time")) -> Delay | V95: =IF(Flights!$U95<>"Delay","",IF(Flights!$T95>120,"Severe",IF(Flights!$T95>60,"Major","Moderate"))) -> Major | W95: =IF(OR(AND(Flights!$U95="Cancel",Flights!$X95="Airline/Carrier"),Flights!$V95="severe"),"Yes","No") -> No
A96: 42012 | B96: =WEEKNUM(Flights!$A96,2) -> 2 | C96: =WEEKDAY(Flights!$A96,2) -> 4 | D96: OO2600 | E96: Skywest | F96: LAX | G96: RDM | H96: =_xlfn.XLOOKUP(Flights!$G96,Airports!$A$2:$A$77,Airports!$D$2:$D$77,"Not Code Found") -> Redmond | I96: =_xlfn.XLOOKUP(Flights!$G96,Airports!$A$2:$A$77,Airports!$E$2:$E$77,"Not Code Found") -> OR | J96: 0.74583333 | K96: =HOUR(Flights!$J96) -> 17 | L96: 0 | O96: =Flights!$N96/60 -> 0 | P96: 726 | Q96: =Flights!$P96/Flights!$O96 -> #DIV/0! | R96: 0.83263889 | S96: 0 | U96: =IF(Flights!$T96="","Cancel",IF(Flights!$T96>15,"Delay","On Time")) -> Cancel | V96: =IF(Flights!$U96<>"Delay","",IF(Flights!$T96>120,"Severe",IF(Flights!$T96>60,"Major","Moderate"))) | W96: =IF(OR(AND(Flights!$U96="Cancel",Flights!$X96="Airline/Carrier"),Flights!$V96="severe"),"Yes","No") -> No | X96: Weather
A97: 42012 | B97: =WEEKNUM(Flights!$A97,2) -> 2 | C97: =WEEKDAY(Flights!$A97,2) -> 4 | D97: WN3588 | E97: Southwest | F97: LAX | G97: OAK | H97: =_xlfn.XLOOKUP(Flights!$G97,Airports!$A$2:$A$77,Airports!$D$2:$D$77,"Not Code Found") -> Oakland | I97: =_xlfn.XLOOKUP(Flights!$G97,Airports!$A$2:$A$77,Airports!$E$2:$E$77,"Not Code Found") -> CA | J97: 0.76388889 | K97: =HOUR(Flights!$J97) -> 18 | L97: 0.76597222 | M97: 3 | N97: 64 | O97: =Flights!$N97/60 -> 1.0666667 | P97: 337 | Q97: =Flights!$P97/Flights!$O97 -> 315.9375 | R97: 0.81597222 | S97: 0.81041667 | T97: -8 | U97: =IF(Flights!$T97="","Cancel",IF(Flights!$T97>15,"Delay","On Time")) -> On Time | V97: =IF(Flights!$U97<>"Delay","",IF(Flights!$T97>120,"Severe",IF(Flights!$T97>60,"Major","Moderate"))) | W97: =IF(OR(AND(Flights!$U97="Cancel",Flights!$X97="Airline/Carrier"),Flights!$V97="severe"),"Yes","No") -> No
A98: 42012 | B98: =WEEKNUM(Flights!$A98,2) -> 2 | C98: =WEEKDAY(Flights!$A98,2) -> 4 | D98: WN816 | E98: Southwest | F98: LAX | G98: OAK | H98: =_xlfn.XLOOKUP(Flights!$G98,Airports!$A$2:$A$77,Airports!$D$2:$D$77,"Not Code Found") -> Oakland | I98: =_xlfn.XLOOKUP(Flights!$G98,Airports!$A$2:$A$77,Airports!$E$2:$E$77,"Not Code Found") -> CA | J98: 0.81597222 | K98: =HOUR(Flights!$J98) -> 19 | L98: 0.81319444 | M98: -4 | N98: 64 | O98: =Flights!$N98/60 -> 1.0666667 | P98: 337 | Q98: =Flights!$P98/Flights!$O98 -> 315.9375 | R98: 0.86805556 | S98: 0.85763889 | T98: -15 | U98: =IF(Flights!$T98="","Cancel",IF(Flights!$T98>15,"Delay","On Time")) -> On Time | V98: =IF(Flights!$U98<>"Delay","",IF(Flights!$T98>120,"Severe",IF(Flights!$T98>60,"Major","Moderate"))) | W98: =IF(OR(AND(Flights!$U98="Cancel",Flights!$X98="Airline/Carrier"),Flights!$V98="severe"),"Yes","No") -> No
A99: 42013 | B99: =WEEKNUM(Flights!$A99,2) -> 2 | C99: =WEEKDAY(Flights!$A99,2) -> 5 | D99: UA1679 | E99: United | F99: LAX | G99: SFO | H99: =_xlfn.XLOOKUP(Flights!$G99,Airports!$A$2:$A$77,Airports!$D$2:$D$77,"Not Code Found") -> San Francisco | I99: =_xlfn.XLOOKUP(Flights!$G99,Airports!$A$2:$A$77,Airports!$E$2:$E$77,"Not Code Found") -> CA | J99: 0.25 | K99: =HOUR(Flights!$J99) -> 6 | L99: 0.40625 | M99: 225 | N99: 67 | O99: =Flights!$N99/60 -> 1.1166667 | P99: 337 | Q99: =Flights!$P99/Flights!$O99 -> 301.79104 | R99: 0.31180556 | S99: 0.45277778 | T99: 203 | U99: =IF(Flights!$T99="","Cancel",IF(Flights!$T99>15,"Delay","On Time")) -> Delay | V99: =IF(Flights!$U99<>"Delay","",IF(Flights!$T99>120,"Severe",IF(Flights!$T99>60,"Major","Moderate"))) -> Severe | W99: =IF(OR(AND(Flights!$U99="Cancel",Flights!$X99="Airline/Carrier"),Flights!$V99="severe"),"Yes","No") -> Yes
A100: 42013 | B100: =WEEKNUM(Flights!$A100,2) -> 2 | C100: =WEEKDAY(Flights!$A100,2) -> 5 | D100: B624 | E100: JetBlue | F100: LAX | G100: JFK | H100: =_xlfn.XLOOKUP(Flights!$G100,Airports!$A$2:$A$77,Airports!$D$2:$D$77,"Not Code Found") -> New York | I100: =_xlfn.XLOOKUP(Flights!$G100,Airports!$A$2:$A$77,Airports!$E$2:$E$77,"Not Code Found") -> NY | J100: 0.27083333 | K100: =HOUR(Flights!$J100) -> 6 | L100: 0.26597222 | M100: -7 | N100: 308 | O100: =Flights!$N100/60 -> 5.1333333 | P100: 2475 | Q100: =Flights!$P100/Flights!$O100 -> 482.14286 | R100: 0.61458333 | S100: 0.60486111 | T100: -14 | U100: =IF(Flights!$T100="","Cancel",IF(Flights!$T100>15,"Delay","On Time")) -> On Time | V100: =IF(Flights!$U100<>"Delay","",IF(Flights!$T100>120,"Severe",IF(Flights!$T100>60,"Major","Moderate"))) | W100: =IF(OR(AND(Flights!$U100="Cancel",Flights!$X100="Airline/Carrier"),Flights!$V100="severe"),"Yes","No") -> No
A101: 42013 | B101: =WEEKNUM(Flights!$A101,2) -> 2 | C101: =WEEKDAY(Flights!$A101,2) -> 5 | D101: UA330 | E101: United | F101: LAX | G101: IAH | H101: =_xlfn.XLOOKUP(Flights!$G101,Airports!$A$2:$A$77,Airports!$D$2:$D$77,"Not Code Found") -> Houston | I101: =_xlfn.XLOOKUP(Flights!$G101,Airports!$A$2:$A$77,Airports!$E$2:$E$77,"Not Code Found") -> TX | J101: 0.28611111 | K101: =HOUR(Flights!$J101) -> 6 | L101: 0.28611111 | M101: 0 | N101: 206 | O101: =Flights!$N101/60 -> 3.4333333 | P101: 1379 | Q101: =Flights!$P101/Flights!$O101 -> 401.65049 | R101: 0.50416667 | S101: 0.5125 | T101: 12 | U101: =IF(Flights!$T101="","Cancel",IF(Flights!$T101>15,"Delay","On Time")) -> On Time | V101: =IF(Flights!$U101<>"Delay","",IF(Flights!$T101>120,"Severe",IF(Flights!$T101>60,"Major","Moderate"))) | W101: =IF(OR(AND(Flights!$U101="Cancel",Flights!$X101="Airline/Carrier"),Flights!$V101="severe"),"Yes","No") -> No
A102: 42013 | B102: =WEEKNUM(Flights!$A102,2) -> 2 | C102: =WEEKDAY(Flights!$A102,2) -> 5 | D102: UA1236 | E102: United | F102: LAX | G102: ORD | H102: =_xlfn.XLOOKUP(Flights!$G102,Airports!$A$2:$A$77,Airports!$D$2:$D$77,"Not Code Found") -> Chicago | I102: =_xlfn.XLOOKUP(Flights!$G102,Airports!$A$2:$A$77,Airports!$E$2:$E$77,"Not Code Found") -> IL | J102: 0.29166667 | K102: =HOUR(Flights!$J102) -> 7 | L102: 0.29305556 | M102: 2 | N102: 279 | O102: =Flights!$N102/60 -> 4.65 | P102: 1744 | Q102: =Flights!$P102/Flights!$O102 -> 375.05376 | R102: 0.54375 | S102: 0.57013889 | T102: 38 | U102: =IF(Flights!$T102="","Cancel",IF(Flights!$T102>15,"Delay","On Time")) -> Delay | V102: =IF(Flights!$U102<>"Delay","",IF(Flights!$T102>120,"Severe",IF(Flights!$T102>60,"Major","Moderate"))) -> Moderate | W102: =IF(OR(AND(Flights!$U102="Cancel",Flights!$X102="Airline/Carrier"),Flights!$V102="severe"),"Yes","No") -> No
A103: 42013 | B103: =WEEKNUM(Flights!$A103,2) -> 2 | C103: =WEEKDAY(Flights!$A103,2) -> 5 | D103: US699 | E103: US Airways | F103: LAX | G103: RDU | H103: =_xlfn.XLOOKUP(Flights!$G103,Airports!$A$2:$A$77,Airports!$D$2:$D$77,"Not Code Found") -> Raleigh | I103: =_xlfn.XLOOKUP(Flights!$G103,Airports!$A$2:$A$77,Airports!$E$2:$E$77,"Not Code Found") -> NC | J103: 0.34027778 | K103: =HOUR(Flights!$J103) -> 8 | L103: 0.3375 | M103: -4 | N103: 285 | O103: =Flights!$N103/60 -> 4.75 | P103: 2239 | Q103: =Flights!$P103/Flights!$O103 -> 471.36842 | R103: 0.65694444 | S103: 0.66041667 | T103: 5 | U103: =IF(Flights!$T103="","Cancel",IF(Flights!$T103>15,"Delay","On Time")) -> On Time | V103: =IF(Flights!$U103<>"Delay","",IF(Flights!$T103>120,"Severe",IF(Flights!$T103>60,"Major","Moderate"))) | W103: =IF(OR(AND(Flights!$U103="Cancel",Flights!$X103="Airline/Carrier"),Flights!$V103="severe"),"Yes","No") -> No
A104: 42013 | B104: =WEEKNUM(Flights!$A104,2) -> 2 | C104: =WEEKDAY(Flights!$A104,2) -> 5 | D104: HA1 | E104: Hawaiian | F104: LAX | G104: HNL | H104: =_xlfn.XLOOKUP(Flights!$G104,Airports!$A$2:$A$77,Airports!$D$2:$D$77,"Not Code Found") -> Honolulu | I104: =_xlfn.XLOOKUP(Flights!$G104,Airports!$A$2:$A$77,Airports!$E$2:$E$77,"Not Code Found") -> HI | J104: 0.36111111 | K104: =HOUR(Flights!$J104) -> 8 | L104: 0.35833333 | M104: -4 | N104: 351 | O104: =Flights!$N104/60 -> 5.85 | P104: 2556 | Q104: =Flights!$P104/Flights!$O104 -> 436.92308 | R104: 0.51736111 | S104: 0.51875 | T104: 2 | U104: =IF(Flights!$T104="","Cancel",IF(Flights!$T104>15,"Delay","On Time")) -> On Time | V104: =IF(Flights!$U104<>"Delay","",IF(Flights!$T104>120,"Severe",IF(Flights!$T104>60,"Major","Moderate"))) | W104: =IF(OR(AND(Flights!$U104="Cancel",Flights!$X104="Airline/Carrier"),Flights!$V104="severe"),"Yes","No") -> No
A105: 42013 | B105: =WEEKNUM(Flights!$A105,2) -> 2 | C105: =WEEKDAY(Flights!$A105,2) -> 5 | D105: AA2 | E105: American Airlines | F105: LAX | G105: JFK | H105: =_xlfn.XLOOKUP(Flights!$G105,Airports!$A$2:$A$77,Airports!$D$2:$D$77,"Not Code Found") -> New York | I105: =_xlfn.XLOOKUP(Flights!$G105,Airports!$A$2:$A$77,Airports!$E$2:$E$77,"Not Code Found") -> NY | J105: 0.375 | K105: =HOUR(Flights!$J105) -> 9 | L105: 0.36944444 | M105: -8 | N105: 319 | O105: =Flights!$N105/60 -> 5.3166667 | P105: 2475 | Q105: =Flights!$P105/Flights!$O105 -> 465.51724 | R105: 0.72847222 | S105: 0.71597222 | T105: -18 | U105: =IF(Flights!$T105="","Cancel",IF(Flights!$T105>15,"Delay","On Time")) -> On Time | V105: =IF(Flights!$U105<>"Delay","",IF(Flights!$T105>120,"Severe",IF(Flights!$T105>60,"Major","Moderate"))) | W105: =IF(OR(AND(Flights!$U105="Cancel",Flights!$X105="Airline/Carrier"),Flights!$V105="severe"),"Yes","No") -> No
A106: 42013 | B106: =WEEKNUM(Flights!$A106,2) -> 2 | C106: =WEEKDAY(Flights!$A106,2) -> 5 | D106: OO2591 | E106: Skywest | F106: LAX | G106: SJC | H106: =_xlfn.XLOOKUP(Flights!$G106,Airports!$A$2:$A$77,Airports!$D$2:$D$77,"Not Code Found") -> San Jose | I106: =_xlfn.XLOOKUP(Flights!$G106,Airports!$A$2:$A$77,Airports!$E$2:$E$77,"Not Code Found") -> CA | J106: 0.41666667 | K106: =HOUR(Flights!$J106) -> 10 | L106: 0.41388889 | M106: -4 | N106: 68 | O106: =Flights!$N106/60 -> 1.1333333 | P106: 308 | Q106: =Flights!$P106/Flights!$O106 -> 271.76471 | R106: 0.46666667 | S106: 0.46111111 | T106: -8 | U106: =IF(Flights!$T106="","Cancel",IF(Flights!$T106>15,"Delay","On Time")) -> On Time | V106: =IF(Flights!$U106<>"Delay","",IF(Flights!$T106>120,"Severe",IF(Flights!$T106>60,"Major","Moderate"))) | W106: =IF(OR(AND(Flights!$U106="Cancel",Flights!$X106="Airline/Carrier"),Flights!$V106="severe"),"Yes","No") -> No
A107: 42013 | B107: =WEEKNUM(Flights!$A107,2) -> 2 | C107: =WEEKDAY(Flights!$A107,2) -> 5 | D107: AS435 | E107: Alaska Airlines | F107: LAX | G107: PDX | H107: =_xlfn.XLOOKUP(Flights!$G107,Airports!$A$2:$A$77,Airports!$D$2:$D$77,"Not Code Found") -> Portland | I107: =_xlfn.XLOOKUP(Flights!$G107,Airports!$A$2:$A$77,Airports!$E$2:$E$77,"Not Code Found") -> OR | J107: 0.43055556 | K107: =HOUR(Flights!$J107) -> 10 | L107: 0.42708333 | M107: -5 | N107: 126 | O107: =Flights!$N107/60 -> 2.1 | P107: 834 | Q107: =Flights!$P107/Flights!$O107 -> 397.14286 | R107: 0.53125 | S107: 0.51458333 | T107: -24 | U107: =IF(Flights!$T107="","Cancel",IF(Flights!$T107>15,"Delay","On Time")) -> On Time | V107: =IF(Flights!$U107<>"Delay","",IF(Flights!$T107>120,"Severe",IF(Flights!$T107>60,"Major","Moderate"))) | W107: =IF(OR(AND(Flights!$U107="Cancel",Flights!$X107="Airline/Carrier"),Flights!$V107="severe"),"Yes","No") -> No
...

Sheet Airports
A1: IATA Code | B1: Airport Name | C1: Address | D1: City | E1: State | F1: Zip Code | G1: FullAddress | H1: Year Opened | I1: Years Open | J1: Contact Email | K1: User | L1: Domain | M1: First Name | N1: Last Name | O1: Full Name
A2: ABQ | B2: Albuquerque International Sunport | C2: 2200 Sunport Blvd SE | D2: Albuquerque | E2: NM | F2: 87106 | G2: =_xlfn.TEXTJOIN(",",TRUE,C2:F2) -> 2200 Sunport Blvd SE,Albuquerque,NM,87106 | H2: 1939 | I2: =YEAR(TODAY())-H2 -> 87 | J2: e.rogers@abqairport.com | K2: =_xlfn.TEXTBEFORE(J2,"@") -> e.rogers | L2: =_xlfn.TEXTBEFORE(_xlfn.TEXTAFTER(J2,"@"),".") -> abqairport | M2: Emily | N2: ROGERS | O2: =M2&" "&LEFT(N2,1) -> Emily R
A3: ANC | B3: Ted Stevens Anchorage International Airport | C3: 5000 W International Airport Rd | D3: Anchorage | E3: AK | F3: 99502 | G3: =_xlfn.TEXTJOIN(",",TRUE,C3:F3) -> 5000 W International Airport Rd,Anchorage,AK,99502 | H3: 1951 | I3: =YEAR(TODAY())-H3 -> 75 | J3: sprice@ancairport.com | K3: =_xlfn.TEXTBEFORE(J3,"@") -> sprice | L3: =_xlfn.TEXTBEFORE(_xlfn.TEXTAFTER(J3,"@"),".") -> ancairport | M3: Steven | N3: PRICE | O3: =M3&" "&LEFT(N3,1) -> Steven P
A4: ASE | B4: Aspen-Pitkin County Airport | C4: 233 E Airport Rd | D4: Aspen | E4: CO | F4: 81611 | G4: =_xlfn.TEXTJOIN(",",TRUE,C4:F4) -> 233 E Airport Rd,Aspen,CO,81611 | H4: 1946 | I4: =YEAR(TODAY())-H4 -> 80 | J4: megan.ward@aspenairport.com | K4: =_xlfn.TEXTBEFORE(J4,"@") -> megan.ward | L4: =_xlfn.TEXTBEFORE(_xlfn.TEXTAFTER(J4,"@"),".") -> aspenairport | M4: Megan | N4: WARD | O4: =M4&" "&LEFT(N4,1) -> Megan W
A5: ATL | B5: Hartsfield-Jackson Atlanta International Airport | C5: 6000 N Terminal Pkwy | D5: Atlanta | E5: GA | F5: 30320 | G5: =_xlfn.TEXTJOIN(",",TRUE,C5:F5) -> 6000 N Terminal Pkwy,Atlanta,GA,30320 | H5: 1925 | I5: =YEAR(TODAY())-H5 -> 101 | J5: cbaker@atlairport.com | K5: =_xlfn.TEXTBEFORE(J5,"@") -> cbaker | L5: =_xlfn.TEXTBEFORE(_xlfn.TEXTAFTER(J5,"@"),".") -> atlairport | M5: Charles | N5: BAKER | O5: =M5&" "&LEFT(N5,1) -> Charles B
A6: AUS | B6: Austin-Bergstrom International Airport | C6: 3600 Presidential Blvd | D6: Austin | E6: TX | F6: 78719 | G6: =_xlfn.TEXTJOIN(",",TRUE,C6:F6) -> 3600 Presidential Blvd,Austin,TX,78719 | H6: 1999 | I6: =YEAR(TODAY())-H6 -> 27 | J6: jedwards@austinairport.com | K6: =_xlfn.TEXTBEFORE(J6,"@") -> jedwards | L6: =_xlfn.TEXTBEFORE(_xlfn.TEXTAFTER(J6,"@"),".") -> austinairport | M6: Julia | N6: EDWARDS | O6: =M6&" "&LEFT(N6,1) -> Julia E
A7: BNA | B7: Nashville International Airport | C7: 1 Terminal Dr | D7: Nashville | E7: TN | F7: 37214 | G7: =_xlfn.TEXTJOIN(",",TRUE,C7:F7) -> 1 Terminal Dr,Nashville,TN,37214 | H7: 1937 | I7: =YEAR(TODAY())-H7 -> 89 | J7: tyler.m@bnaairport.com | K7: =_xlfn.TEXTBEFORE(J7,"@") -> tyler.m | L7: =_xlfn.TEXTBEFORE(_xlfn.TEXTAFTER(J7,"@"),".") -> bnaairport | M7: Tyler | N7: MORGAN | O7: =M7&" "&LEFT(N7,1) -> Tyler M
A8: BOI | B8: Boise Airport | C8: 3201 W Airport Way | D8: Boise | E8: ID | F8: 83705 | G8: =_xlfn.TEXTJOIN(",",TRUE,C8:F8) -> 3201 W Airport Way,Boise,ID,83705 | H8: 1936 | I8: =YEAR(TODAY())-H8 -> 90 | J8: angie.stewart@boiairport.com | K8: =_xlfn.TEXTBEFORE(J8,"@") -> angie.stewart | L8: =_xlfn.TEXTBEFORE(_xlfn.TEXTAFTER(J8,"@"),".") -> boiairport | M8: Angela | N8: STEWART | O8: =M8&" "&LEFT(N8,1) -> Angela S
A9: BOS | B9: Gen. Edward Lawrence Logan International Airport | C9: 1 Harborside Dr | D9: Boston | E9: MA | F9: 02128 | G9: =_xlfn.TEXTJOIN(",",TRUE,C9:F9) -> 1 Harborside Dr,Boston,MA,02128 | H9: 1923 | I9: =YEAR(TODAY())-H9 -> 103 | J9: mlee@loganairport.com | K9: =_xlfn.TEXTBEFORE(J9,"@") -> mlee | L9: =_xlfn.TEXTBEFORE(_xlfn.TEXTAFTER(J9,"@"),".") -> loganairport | M9: Matthew | N9: LEE | O9: =M9&" "&LEFT(N9,1) -> Matthew L
A10: BWI | B10: Baltimore-Washington International Airport | C10: 7050 Friendship Rd | D10: Baltimore | E10: MD | F10: 21240 | G10: =_xlfn.TEXTJOIN(",",TRUE,C10:F10) -> 7050 Friendship Rd,Baltimore,MD,21240 | H10: 1950 | I10: =YEAR(TODAY())-H10 -> 76 | J10: jhoward@bwiairport.com | K10: =_xlfn.TEXTBEFORE(J10,"@") -> jhoward | L10: =_xlfn.TEXTBEFORE(_xlfn.TEXTAFTER(J10,"@"),".") -> bwiairport | M10: Jessica | N10: HOWARD | O10: =M10&" "&LEFT(N10,1) -> Jessica H
A11: BZN | B11: Bozeman Yellowstone International Airport | C11: 850 Gallatin Field Rd | D11: Bozeman | E11: MT | F11: 59714 | G11: =_xlfn.TEXTJOIN(",",TRUE,C11:F11) -> 850 Gallatin Field Rd,Bozeman,MT,59714 | H11: 1942 | I11: =YEAR(TODAY())-H11 -> 84 | J11: rphillips@bozemanairport.com | K11: =_xlfn.TEXTBEFORE(J11,"@") -> rphillips | L11: =_xlfn.TEXTBEFORE(_xlfn.TEXTAFTER(J11,"@"),".") -> bozemanairport | M11: Ryan | N11: PHILLIPS | O11: =M11&" "&LEFT(N11,1) -> Ryan P
A12: CLD | B12: McClellan-Palomar Airport | C12: 2198 Palomar Airport Rd | D12: San Diego | E12: CA | F12: 92011 | G12: =_xlfn.TEXTJOIN(",",TRUE,C12:F12) -> 2198 Palomar Airport Rd,San Diego,CA,92011 | H12: 1959 | I12: =YEAR(TODAY())-H12 -> 67 | J12: ladams@carlsbadairport.com | K12: =_xlfn.TEXTBEFORE(J12,"@") -> ladams | L12: =_xlfn.TEXTBEFORE(_xlfn.TEXTAFTER(J12,"@"),".") -> carlsbadairport | M12: Lauren | N12: ADAMS | O12: =M12&" "&LEFT(N12,1) -> Lauren A
A13: CLE | B13: Cleveland Hopkins International Airport | C13: 5300 Riverside Dr | D13: Cleveland | E13: OH | F13: 44135 | G13: =_xlfn.TEXTJOIN(",",TRUE,C13:F13) -> 5300 Riverside Dr,Cleveland,OH,44135 | H13: 1925 | I13: =YEAR(TODAY())-H13 -> 101 | J13: bclark@cleairport.com | K13: =_xlfn.TEXTBEFORE(J13,"@") -> bclark | L13: =_xlfn.TEXTBEFORE(_xlfn.TEXTAFTER(J13,"@"),".") -> cleairport | M13: Benjamin | N13: CLARK | O13: =M13&" "&LEFT(N13,1) -> Benjamin C
... A36: JAC | B36: Jackson Hole Airport | C36: 1250 E Airport Rd | D36: Jackson | E36: WY | F36: 83001 | G36: =_xlfn.TEXTJOIN(",",TRUE,C36:F36) -> 1250 E Airport Rd,Jackson,WY,83001 | H36: 1930 | I36: =YEAR(TODAY())-H36 -> 96 | J36: sbarrett@jacksonholeairport.com | K36: =_xlfn.TEXTBEFORE(J36,"@") -> sbarrett | L36: =_xlfn.TEXTBEFORE(_xlfn.TEXTAFTER(J36,"@"),".") -> jacksonholeairport | M36: Scott | N36: BARRETT | O36: =M36&" "&LEFT(N36,1) -> Scott B
A37: JFK | B37: John F. Kennedy International Airport | D37: New York | E37: NY | F37: 11430 | G37: =_xlfn.TEXTJOIN(",",TRUE,C37:F37) -> New York,NY,11430 | H37: 1948 | I37: =YEAR(TODAY())-H37 -> 78 | J37: d.bennett@jfkairport.com | K37: =_xlfn.TEXTBEFORE(J37,"@") -> d.bennett | L37: =_xlfn.TEXTBEFORE(_xlfn.TEXTAFTER(J37,"@"),".") -> jfkairport | M37: David | N37: BENNETT | O37: =M37&" "&LEFT(N37,1) -> David B
A38: KOA | B38: Kona International Airport at Keahole | C38: 73-200 Kupipi St | D38: Kona | E38: HI | F38: 96740 | G38: =_xlfn.TEXTJOIN(",",TRUE,C38:F38) -> 73-200 Kupipi St,Kona,HI,96740 | H38: 1970 | I38: =YEAR(TODAY())-H38 -> 56 | J38: vreynolds@konaairport.com | K38: =_xlfn.TEXTBEFORE(J38,"@") -> vreynolds | L38: =_xlfn.TEXTBEFORE(_xlfn.TEXTAFTER(J38,"@"),".") -> konaairport | M38: Victoria | N38: REYNOLDS | O38: =M38&" "&LEFT(N38,1) -> Victoria R
A39: LAS | B39: McCarran International Airport | C39: 5757 Wayne Newton Blvd | D39: Las Vegas | E39: NV | F39: 89119 | G39: =_xlfn.TEXTJOIN(",",TRUE,C39:F39) -> 5757 Wayne Newton Blvd,Las Vegas,NV,89119 | H39: 1942 | I39: =YEAR(TODAY())-H39 -> 84 | J39: jcollins@lasairport.com | K39: =_xlfn.TEXTBEFORE(J39,"@") -> jcollins | L39: =_xlfn.TEXTBEFORE(_xlfn.TEXTAFTER(J39,"@"),".") -> lasairport | M39: Joshua | N39: COLLINS | O39: =M39&" "&LEFT(N39,1) -> Joshua C
A40: LIH | B40: Lihue Airport | C40: 3901 Mokulele Loop | D40: Lihue | E40: HI | F40: 96766 | G40: =_xlfn.TEXTJOIN(",",TRUE,C40:F40) -> 3901 Mokulele Loop,Lihue,HI,96766 | H40: 1950 | I40: =YEAR(TODAY())-H40 -> 76 | J40: monica.f@lihueairport.com | K40: =_xlfn.TEXTBEFORE(J40,"@") -> monica.f | L40: =_xlfn.TEXTBEFORE(_xlfn.TEXTAFTER(J40,"@"),".") -> lihueairport | M40: Monica | N40: FLORES | O40: =M40&" "&LEFT(N40,1) -> Monica F
A41: MCI | B41: Kansas City International Airport | C41: 1 International Square | D41: Kansas City | E41: MO | F41: 64153 | G41: =_xlfn.TEXTJOIN(",",TRUE,C41:F41) -> 1 International Square,Kansas City,MO,64153 | H41: 1972 | I41: =YEAR(TODAY())-H41 -> 54 | J41: rtorres@flykc.com | K41: =_xlfn.TEXTBEFORE(J41,"@") -> rtorres | L41: =_xlfn.TEXTBEFORE(_xlfn.TEXTAFTER(J41,"@"),".") -> flykc | M41: Richard | N41: TORRES | O41: =M41&" "&LEFT(N41,1) -> Richard T
A42: MCO | B42: Orlando International Airport | C42: 1 Jeff Fuqua Blvd | D42: Orlando | E42: FL | F42: 32827 | G42: =_xlfn.TEXTJOIN(",",TRUE,C42:F42) -> 1 Jeff Fuqua Blvd,Orlando,FL,32827 | H42: 1981 | I42: =YEAR(TODAY())-H42 -> 45 | J42: b.campbell@orlandoairports.net | K42: =_xlfn.TEXTBEFORE(J42,"@") -> b.campbell | L42: =_xlfn.TEXTBEFORE(_xlfn.TEXTAFTER(J42,"@"),".") -> orlandoairports | M42: Brooke | N42: CAMPBELL | O42: =M42&" "&LEFT(N42,1) -> Brooke C
A43: MDW | B43: Chicago Midway International Airport | C43: 5700 S Cicero Ave | D43: Chicago | E43: IL | F43: 60638 | G43: =_xlfn.TEXTJOIN(",",TRUE,C43:F43) -> 5700 S Cicero Ave,Chicago,IL,60638 | H43: 1927 | I43: =YEAR(TODAY())-H43 -> 99 | J43: jmorgan@mdwairport.com | K43: =_xlfn.TEXTBEFORE(J43,"@") -> jmorgan | L43: =_xlfn.TEXTBEFORE(_xlfn.TEXTAFTER(J43,"@"),".") -> mdwairport | M43: Jacob | N43: MORGAN | O43: =M43&" "&LEFT(N43,1) -> Jacob M
A44: MEM | B44: Memphis International Airport | C44: 2491 Winchester Rd | D44: Memphis | E44: TN | F44: 38116 | G44: =_xlfn.TEXTJOIN(",",TRUE,C44:F44) -> 2491 Winchester Rd,Memphis,TN,38116 | H44: 1929 | I44: =YEAR(TODAY())-H44 -> 97 | J44: cwatson@memairport.com | K44: =_xlfn.TEXTBEFORE(J44,"@") -> cwatson | L44: =_xlfn.TEXTBEFORE(_xlfn.TEXTAFTER(J44,"@"),".") -> memairport | M44: Caroline | N44: WATSON | O44: =M44&" "&LEFT(N44,1) -> Caroline W
A45: MIA | B45: Miami International Airport | C45: 2100 NW 42nd Ave | D45: Miami | E45: FL | F45: 33142 | G45: =_xlfn.TEXTJOIN(",",TRUE,C45:F45) -> 2100 NW 42nd Ave,Miami,FL,33142 | H45: 1928 | I45: =YEAR(TODAY())-H45 -> 98 | J45: tkelly@miairport.com | K45: =_xlfn.TEXTBEFORE(J45,"@") -> tkelly | L45: =_xlfn.TEXTBEFORE(_xlfn.TEXTAFTER(J45,"@"),".") -> miairport | M45: Thomas | N45: KELLY | O45: =M45&" "&LEFT(N45,1) -> Thomas
A46: MKE | B46: General Mitchell International Airport | C46: 5300 S Howell Ave | D46: Milwaukee | E46: WI | F46: 53207 | G46: =_xlfn.TEXTJOIN(",",TRUE,C46:F46) -> 5300 S Howell Ave,Milwaukee,WI,53207 | H46: 1927 | I46: =YEAR(TODAY())-H46 -> 99 | J46: njones@mkeairport.com | K46: =_xlfn.TEXTBEFORE(J46,"@") -> njones | L46: =_xlfn.TEXTBEFORE(_xlfn.TEXTAFTER(J46,"@"),".") -> mkeairport | M46: Natalie | N46: JONES | O46: =M46&" "&LEFT(N46,1) -> Natalie J
A47: MRY | B47: Monterey Regional Airport | C47: 200 Fred Kane Dr | D47: Monterey | E47: CA | F47: 93940 | G47: =_xlfn.TEXTJOIN(",",TRUE,C47:F47) -> 200 Fred Kane Dr,Monterey,CA,93940 | H47: 1936 | I47: =YEAR(TODAY())-H47 -> 90 | J47: ethan.b@montereyairport.com | K47: =_xlfn.TEXTBEFORE(J47,"@") -> ethan.b | L47: =_xlfn.TEXTBEFORE(_xlfn.TEXTAFTER(J47,"@"),".") -> montereyairport | M47: Ethan | N47: BENNETT | O47: =M47&" "&LEFT(N47,1) -> Ethan B
A48: MSP | B48: Minneapolis-Saint Paul International Airport | C48: 4300 Glumack Dr | D48: Minneapolis | E48: MN | F48: 55111 | G48: =_xlfn.TEXTJOIN(",",TRUE,C48:F48) -> 4300 Glumack Dr,Minneapolis,MN,55111 | H48: 1920 | I48: =YEAR(TODAY())-H48 -> 106 | J48: acruz@mspairport.com | K48: =_xlfn.TEXTBEFORE(J48,"@") -> acruz | L48: =_xlfn.TEXTBEFORE(_xlfn.TEXTAFTER(J48,"@"),".") -> mspairport | M48: Amanda | N48: CRUZ | O48: =M48&" "&LEFT(N48,1) -> Amanda C
A49: MSY | B49: Louis Armstrong New Orleans International Airport | C49: 1 Terminal Dr | D49: New Orleans | E49: LA | F49: 70062 | G49: =_xlfn.TEXTJOIN(",",TRUE,C49:F49) -> 1 Terminal Dr,New Orleans,LA,70062 | H49: 1946 | I49: =YEAR(TODAY())-H49 -> 80 | J49: jbrooks@flymsy.com | K49: =_xlfn.TEXTBEFORE(J49,"@") -> jbrooks | L49: =_xlfn.TEXTBEFORE(_xlfn.TEXTAFTER(J49,"@"),".") -> flymsy | M49: Jason | N49: BROOKS | O49: =M49&" "&LEFT(N49,1) -> Jason B
... A69: SEA | B69: Seattle-Tacoma International Airport | C69: 17801 International Blvd | D69: Seattle | E69: WA | F69: 98158 | G69: =_xlfn.TEXTJOIN(",",TRUE,C69:F69) -> 17801 International Blvd,Seattle,WA,98158 | H69: 1944 | I69: =YEAR(TODAY())-H69 -> 82 | J69: k.edwards@sea-tac.com | K69: =_xlfn.TEXTBEFORE(J69,"@") -> k.edwards | L69: =_xlfn.TEXTBEFORE(_xlfn.TEXTAFTER(J69,"@"),".") -> sea-tac | M69: Rachel | N69: COOPER | O69: =M69&" "&LEFT(N69,1) -> Rachel C
A70: SFO | B70: San Francisco International Airport | D70: San Francisco | E70: CA | F70: 94128 | G70: =_xlfn.TEXTJOIN(",",TRUE,C70:F70) -> San Francisco,CA,94128 | H70: 1927 | I70: =YEAR(TODAY())-H70 -> 99 | J70: j.hall@flysfo.com | K70: =_xlfn.TEXTBEFORE(J70,"@") -> j.hall | L70: =_xlfn.TEXTBEFORE(_xlfn.TEXTAFTER(J70,"@"),".") -> flysfo | M70: James | N70: BENNETT | O70: =M70&" "&LEFT(N70,1) -> James B
A71: SJC | B71: Norman Y. Mineta San José International Airport | C71: 1701 Airport Blvd | D71: San Jose | E71: CA | F71: 95110 | G71: =_xlfn.TEXTJOIN(",",TRUE,C71:F71) -> 1701 Airport Blvd,San Jose,CA,95110 | H71: 1945 | I71: =YEAR(TODAY())-H71 -> 81 | J71: s.campbell@sjcairport.com | K71: =_xlfn.TEXTBEFORE(J71,"@") -> s.campbell | L71: =_xlfn.TEXTBEFORE(_xlfn.TEXTAFTER(J71,"@"),".") -> sjcairport | M71: Natalie | N71: PARKER | O71: =M71&" "&LEFT(N71,1) -> Natalie P
A72: SLC | B72: Salt Lake City International Airport | C72: 776 N Terminal Dr | D72: Salt Lake City | E72: UT | F72: 84122 | G72: =_xlfn.TEXTJOIN(",",TRUE,C72:F72) -> 776 N Terminal Dr,Salt Lake City,UT,84122 | H72: 1911 | I72: =YEAR(TODAY())-H72 -> 115 | J72: w.wright@slcairport.com | K72: =_xlfn.TEXTBEFORE(J72,"@") -> w.wright | L72: =_xlfn.TEXTBEFORE(_xlfn.TEXTAFTER(J72,"@"),".") -> slcairport | M72: David | N72: HAMILTON | O72: =M72&" "&LEFT(N72,1) -> David H
A73: SMF | B73: Sacramento International Airport | C73: 6900 Airport Blvd | D73: Sacramento | E73: CA | F73: 95837 | G73: =_xlfn.TEXTJOIN(",",TRUE,C73:F73) -> 6900 Airport Blvd,Sacramento,CA,95837 | H73: 1967 | I73: =YEAR(TODAY())-H73 -> 59 | J73: n.parker@sacairport.com | K73: =_xlfn.TEXTBEFORE(J73,"@") -> n.parker | L73: =_xlfn.TEXTBEFORE(_xlfn.TEXTAFTER(J73,"@"),".") -> sacairport | M73: Olivia | N73: TORRES | O73: =M73&" "&LEFT(N73,1) -> Olivia T
A74: SMX | B74: Santa Maria Public Airport | C74: 3249 Terminal Dr | D74: Santa Maria | E74: CA | F74: 93455 | G74: =_xlfn.TEXTJOIN(",",TRUE,C74:F74) -> 3249 Terminal Dr,Santa Maria,CA,93455 | H74: 1946 | I74: =YEAR(TODAY())-H74 -> 80 | J74: l.scott@santamariaairport.com | K74: =_xlfn.TEXTBEFORE(J74,"@") -> l.scott | L74: =_xlfn.TEXTBEFORE(_xlfn.TEXTAFTER(J74,"@"),".") -> santamariaairport | M74: Andrew | N74: MILLER | O74: =M74&" "&LEFT(N74,1) -> Andrew M
A75: STL | B75: St. Louis International Airport at Lambert Field | C75: 10701 Lambert International Blvd | D75: St. Louis | E75: MO | F75: 63145 | G75: =_xlfn.TEXTJOIN(",",TRUE,C75:F75) -> 10701 Lambert International Blvd,St. Louis,MO,63145 | H75: 1920 | I75: =YEAR(TODAY())-H75 -> 106 | J75: m.garcia@flystl.com | K75: =_xlfn.TEXTBEFORE(J75,"@") -> m.garcia | L75: =_xlfn.TEXTBEFORE(_xlfn.TEXTAFTER(J75,"@"),".") -> flystl | M75: Mark | N75: THOMPSON | O75: =M75&" "&LEFT(N75,1) -> Mark T
A76: TPA | B76: Tampa International Airport | C76: 4100 George J Bean Pkwy | D76: Tampa | E76: FL | F76: 33607 | G76: =_xlfn.TEXTJOIN(",",TRUE,C76:F76) -> 4100 George J Bean Pkwy,Tampa,FL,33607 | H76: 1928 | I76: =YEAR(TODAY())-H76 -> 98 | J76: c.evans@tampaairport.com | K76: =_xlfn.TEXTBEFORE(J76,"@") -> c.evans | L76: =_xlfn.TEXTBEFORE(_xlfn.TEXTAFTER(J76,"@"),".") -> tampaairport | M76: Hannah | N76: BROOKS | O76: =M76&" "&LEFT(N76,1) -> Hannah B
A77: TUS | B77: Tucson International Airport | C77: 7250 S Tucson Blvd | D77: Tucson | E77: AZ | F77: 85756 | G77: =_xlfn.TEXTJOIN(",",TRUE,C77:F77) -> 7250 S Tucson Blvd,Tucson,AZ,85756 | H77: 1919 | I77: =YEAR(TODAY())-H77 -> 107 | J77: d.mitchell@flytucson.com | K77: =_xlfn.TEXTBEFORE(J77,"@") -> d.mitchell | L77: =_xlfn.TEXTBEFORE(_xlfn.TEXTAFTER(J77,"@"),".") -> flytucson | M77: William | N77: SCOTT | O77: =M77&" "&LEFT(N77,1) -> William S

Sheet 2016 Forecasts
B2: 2016 Forecasts
C4: Target YoY growth: | D4: 0.03 | F4: Cancellation %: | G4: 0.02 | H4: 0.015 | I4: 0.05
B6: Month | C6: 2015 Flights | D6: 2016 Forecast | F6: Month | G6: Airline/Carrier | H6: National Air System | I6: Weather
B7: January | C7: 389 | D7: {=ROUND(C7:C18 * (100%+D4),0)} -> 401 | F7: January | G7: {=ROUND(_xlfn.ANCHORARRAY(D7)*G4:I4,0)} -> 8 | H7: 6 | I7: 20
B8: February | C8: 356 | D8: 367 | F8: February | G8: 7 | H8: 6 | I8: 18
B9: March | C9: 405 | D9: 417 | F9: March | G9: 8 | H9: 6 | I9: 21
B10: April | C10: 391 | D10: 403 | F10: April | G10: 8 | H10: 6 | I10: 20
B11: May | C11: 448 | D11: 461 | F11: May | G11: 9 | H11: 7 | I11: 23
B12: June | C12: 417 | D12: 430 | F12: June | G12: 9 | H12: 6 | I12: 22
B13: July | C13: 476 | D13: 490 | F13: July | G13: 10 | H13: 7 | I13: 25
B14: August | C14: 457 | D14: 471 | F14: August | G14: 9 | H14: 7 | I14: 24
B15: September | C15: 437 | D15: 450 | F15: September | G15: 9 | H15: 7 | I15: 23
B16: October | C16: 405 | D16: 417 | F16: October | G16: 8 | H16: 6 | I16: 21
B17: November | C17: 390 | D17: 402 | F17: November | G17: 8 | H17: 6 | I17: 20
B18: December | C18: 414 | D18: 426 | F18: December | G18: 9 | H18: 6 | I18: 21
B19: Total: | C19: =SUM(C7:C18) -> 4985 | D19: =SUM(_xlfn.ANCHORARRAY(D7)) -> 5135
B20: Average: | C20: =AVERAGE(C7:C18) -> 415.41667 | D20: =AVERAGE(_xlfn.ANCHORARRAY(D7)) -> 427.91667
B21: Max: | C21: =MAX(C7:C18) -> 476 | D21: =MAX(_xlfn.ANCHORARRAY(D7)) -> 490

Sheet Report
A1: Report LAX Flights
B4: Flights: | C4: =COUNTA(Flights[Flight]) -> 4985
B5: Delays: | C5: =COUNTIFS(Flights[Status],"Delay") -> 975
B6: Avg. Delay: | C6: =AVERAGEIFS(Flights[Arrival Delay],Flights[Status],"Delay") -> 51.867692
B7: Cancellations: | C7: =C4-COUNTBLANK(Flights[Cancellation Reason]) -> 53
B8: Destinations: | C8: =COUNTA(_xlfn.UNIQUE(Flights[Destination])) -> 76
B11: Airline | C11: Flights | D11: On time | E11: Delay | F11: Cancel
B12: {=_xlfn._xlws.SORT(_xlfn.UNIQUE(Flights[Airline]))} -> Alaska Airlines | C12: {=COUNTIFS(Flights[Airline],_xlfn.ANCHORARRAY(B12))} -> 235 | D12: {=COUNTIFS(Flights[Airline],_xlfn.ANCHORARRAY(B12),Flights[Status],D11:F11)/_xlfn.ANCHORARRAY(C12)} -> 0.91489362 | E12: 0.080851064 | F12: 0.0042553191
B13: American Airlines | C13: 839 | D13: 0.84028605 | E13: 0.15256257 | F13: 0.0071513707
B14: Delta | C14: 654 | D14: 0.84556575 | E14: 0.1529052 | F14: 0.001529052
B15: Frontier | C15: 41 | D15: 0.75609756 | E15: 0.24390244 | F15: 0
B16: Hawaiian | C16: 38 | D16: 0.73684211 | E16: 0.23684211 | F16: 0.026315789
B17: JetBlue | C17: 108 | D17: 0.7962963 | E17: 0.2037037 | F17: 0
B18: Skywest | C18: 874 | D18: 0.76315789 | E18: 0.21967963 | F18: 0.017162471
B19: Southwest | C19: 971 | D19: 0.73326468 | E19: 0.24819773 | F19: 0.01853759
B20: Spirit | C20: 120 | D20: 0.66666667 | E20: 0.325 | F20: 0.0083333333
B21: United | C21: 703 | D21: 0.79231863 | E21: 0.19630156 | F21: 0.011379801
B22: US Airways | C22: 102 | D22: 0.82352941 | E22: 0.16666667 | F22: 0.0098039216
B23: Virgin America | C23: 300 | D23: 0.79666667 | E23: 0.2 | F23: 0.0033333333
